bioimageio_core_version: 0.5.3.post2
bioimageio_spec_version: 0.4.8.post1
rdf_sha256: 319726182caa558c3f1040e2e9bbf846f88915289569b94b3330c8dbf9f8c5af
status: failed
tests:
  bioimageio:
  - bioimageio_spec_version: 0.4.8post1
    error: null
    name: bioimageio.spec static validation of model RDF 0.4.8 with update to latest
      format version
    nested_errors: {}
    status: passed
    traceback: null
    warnings: {}
  - bioimageio_spec_version: 0.4.8post1
    error: null
    name: bioimageio.spec static validation of model RDF 0.4.8
    nested_errors: {}
    status: passed
    traceback: null
    warnings: {}
  - error: No module named 'tqdm'
    name: import test_resource from test environment
    status: failed
    traceback: ["  File \"scripts/dynamic_validation.py\", line 41, in main\n    from
        bioimageio.core.resource_tests import test_resource\n", "  File \"/home/runner/micromamba-root/envs/6348085/lib/python3.7/site-packages/bioimageio/core/__init__.py\",
        line 13, in <module>\n    from .prediction_pipeline import create_prediction_pipeline\n",
      "  File \"/home/runner/micromamba-root/envs/6348085/lib/python3.7/site-packages/bioimageio/core/prediction_pipeline/__init__.py\",
        line 2, in <module>\n    from ._prediction_pipeline import PredictionPipeline,
        create_prediction_pipeline\n", "  File \"/home/runner/micromamba-root/envs/6348085/lib/python3.7/site-packages/bioimageio/core/prediction_pipeline/_prediction_pipeline.py\",
        line 12, in <module>\n    from ._stat_state import StatsState\n", "  File
        \"/home/runner/micromamba-root/envs/6348085/lib/python3.7/site-packages/bioimageio/core/prediction_pipeline/_stat_state.py\",
        line 3, in <module>\n    from tqdm import tqdm\n"]
  deepimagej:
  - {bioimageio_spec_version: 0.4.8post1, name: Reproduce test outputs with DeepImageJ
      headless, status: passed}
  ilastik:
  - bioimageio_core_version: 0.5.1
    bioimageio_spec_version: 0.4.5post3
    error: '{''format_version'': [''Must be one of: 0.4.0, 0.4.1, 0.4.2, 0.4.3, 0.4.4,
      0.4.5.'']}'
    name: reproduce test outputs with ilastik 1.4.0b26 using tensorflow_saved_model_bundle
      weights
    reason: error
    status: failed
    traceback: ["  File \"/usr/share/miniconda3/envs/ilastik-env/lib/python3.7/site-packages/bioimageio/core/resource_tests.py\",
        line 39, in test_model\n    model_rdf, weights_priority_order=None if weight_format
        is None else [weight_format]\n", "  File \"/usr/share/miniconda3/envs/ilastik-env/lib/python3.7/site-packages/bioimageio/core/resource_io/io_.py\",
        line 41, in load_resource_description\n    raw_rd = load_raw_resource_description(source,
        update_to_format=\"latest\")\n", "  File \"/usr/share/miniconda3/envs/ilastik-env/lib/python3.7/site-packages/bioimageio/spec/io_.py\",
        line 191, in load_raw_resource_description\n    raw_rd = schema.load(data)\n",
      "  File \"/usr/share/miniconda3/envs/ilastik-env/lib/python3.7/site-packages/marshmallow/schema.py\",
        line 718, in load\n    data, many=many, partial=partial, unknown=unknown,
        postprocess=True\n", "  File \"/usr/share/miniconda3/envs/ilastik-env/lib/python3.7/site-packages/marshmallow/schema.py\",
        line 900, in _do_load\n    raise exc\n"]
  - bioimageio_core_version: 0.5.3post2
    bioimageio_spec_version: 0.4.5post6
    error: '{''format_version'': [''Must be one of: 0.4.0, 0.4.1, 0.4.2, 0.4.3, 0.4.4,
      0.4.5.'']}'
    name: reproduce test outputs with ilastik 1.4.0b27 using tensorflow_saved_model_bundle
      weights
    reason: error
    status: failed
    traceback: ["  File \"/usr/share/miniconda3/envs/ilastik-env/lib/python3.7/site-packages/bioimageio/core/resource_tests.py\",
        line 39, in test_model\n    model_rdf, weights_priority_order=None if weight_format
        is None else [weight_format]\n", "  File \"/usr/share/miniconda3/envs/ilastik-env/lib/python3.7/site-packages/bioimageio/core/resource_io/io_.py\",
        line 47, in load_resource_description\n    raw_rd = load_raw_resource_description(source,
        update_to_format=\"latest\")\n", "  File \"/usr/share/miniconda3/envs/ilastik-env/lib/python3.7/site-packages/bioimageio/spec/io_.py\",
        line 197, in load_raw_resource_description\n    raw_rd = schema.load(data)\n",
      "  File \"/usr/share/miniconda3/envs/ilastik-env/lib/python3.7/site-packages/marshmallow/schema.py\",
        line 718, in load\n    data, many=many, partial=partial, unknown=unknown,
        postprocess=True\n", "  File \"/usr/share/miniconda3/envs/ilastik-env/lib/python3.7/site-packages/marshmallow/schema.py\",
        line 900, in _do_load\n    raise exc\n"]
  - {error: Missing/invalid weight formats for 10.5281/zenodo.6348084/6348085, name: reproduce
      test outputs with ilastik 1.4.0b27, reason: error, status: failed}
  - bioimageio_core_version: 0.5.8
    bioimageio_spec_version: 0.4.9
    error: null
    name: load resource description
    nested_errors: null
    status: passed
    traceback: null
    warnings: {}
  - {error: null, name: has expected resource type, status: passed, traceback: null}
  - bioimageio_core_version: 0.5.8
    bioimageio_spec_version: 0.4.9
    error: null
    name: All URLs and paths available
    nested_errors: null
    status: passed
    traceback: null
    warnings: {}
  - bioimageio_core_version: 0.5.8
    bioimageio_spec_version: 0.4.9
    error: null
    name: Test documentation completeness.
    status: passed
    traceback: null
    warnings: {documentation: No '# Validation' (sub)section found.}
  - bioimageio_core_version: 0.5.8
    bioimageio_spec_version: 0.4.9
    error: null
    name: reproduce test outputs from test inputs
    status: passed
    traceback: null
    warnings:
      non-validation-warnings: ['Model tensorflow version (1, 15) does not match 1.14.0.The
          prediction results may be wrong', Computed dataset percentiles naively by
          averaging percentiles of samples., 'Device management is not implemented
          for keras yet, cannot unload model']
  - {error: Missing/invalid weight formats for 10.5281/zenodo.6348084/6348085, name: reproduce
      test outputs with ilastik 1.4.0b26, reason: error, status: failed}
  - bioimageio_core_version: 0.5.7
    bioimageio_spec_version: 0.4.8
    error: null
    name: load resource description
    status: passed
    traceback: null
    warnings: {}
  - {error: null, name: has expected resource type, status: passed, traceback: null}
  - bioimageio_core_version: 0.5.7
    bioimageio_spec_version: 0.4.8
    error: null
    name: All URLs and paths available
    nested_errors: null
    status: passed
    traceback: null
    warnings: {}
  - bioimageio_core_version: 0.5.7
    bioimageio_spec_version: 0.4.8
    error: null
    name: Test documentation completeness.
    status: passed
    traceback: null
    warnings: {documentation: No '# Validation' (sub)section found.}
  - bioimageio_core_version: 0.5.7
    bioimageio_spec_version: 0.4.8
    error: null
    name: reproduce test outputs from test inputs
    status: passed
    traceback: null
    warnings:
      non-validation-warnings: [Computed dataset percentiles naively by averaging
          percentiles of samples., 'Model tensorflow version (1, 15) does not match
          1.14.0.The prediction results may be wrong', 'Device management is not implemented
          for keras yet, cannot unload model']
