bioimageio_core_version: 0.5.3.post2
bioimageio_spec_version: 0.4.8.post1
rdf_sha256: c627435a2ab85e1e27f9bd1e5416f16cc4386f181cbfccbe07740edc5c37e7d6
status: failed
tests:
  bioimageio:
  - bioimageio_spec_version: 0.4.8post1
    error: null
    name: bioimageio.spec static validation of model RDF 0.4.8 with update to latest
      format version
    nested_errors: {}
    status: passed
    traceback: null
    warnings: {tags: 'Missing tags for categories: [{''task'': [''semantic-segmentation'',
        ''instance-segmentation'', ''object-detection'', ''image-classification'',
        ''denoising'', ''image-restoration'', ''image-reconstruction'', ''in-silico-labeling'']}]'}
  - bioimageio_spec_version: 0.4.8post1
    error: null
    name: bioimageio.spec static validation of model RDF 0.4.8
    nested_errors: {}
    status: passed
    traceback: null
    warnings: {tags: 'Missing tags for categories: [{''task'': [''semantic-segmentation'',
        ''instance-segmentation'', ''object-detection'', ''image-classification'',
        ''denoising'', ''image-restoration'', ''image-reconstruction'', ''in-silico-labeling'']}]'}
  - error: No module named 'tqdm'
    name: import test_resource from test environment
    status: failed
    traceback: ["  File \"scripts/dynamic_validation.py\", line 41, in main\n    from
        bioimageio.core.resource_tests import test_resource\n", "  File \"/home/runner/micromamba-root/envs/5888237/lib/python3.7/site-packages/bioimageio/core/__init__.py\",
        line 13, in <module>\n    from .prediction_pipeline import create_prediction_pipeline\n",
      "  File \"/home/runner/micromamba-root/envs/5888237/lib/python3.7/site-packages/bioimageio/core/prediction_pipeline/__init__.py\",
        line 2, in <module>\n    from ._prediction_pipeline import PredictionPipeline,
        create_prediction_pipeline\n", "  File \"/home/runner/micromamba-root/envs/5888237/lib/python3.7/site-packages/bioimageio/core/prediction_pipeline/_prediction_pipeline.py\",
        line 12, in <module>\n    from ._stat_state import StatsState\n", "  File
        \"/home/runner/micromamba-root/envs/5888237/lib/python3.7/site-packages/bioimageio/core/prediction_pipeline/_stat_state.py\",
        line 3, in <module>\n    from tqdm import tqdm\n"]
  deepimagej:
  - {bioimageio_spec_version: 0.4.8post1, error: Difference between CI and expected
      outputs is greater than threshold (CI produced an output image), name: Reproduce
      test outputs with DeepImageJ headless, status: failed}
  ilastik:
  - bioimageio_core_version: 0.5.1
    bioimageio_spec_version: 0.4.5post3
    error: '{''format_version'': [''Must be one of: 0.4.0, 0.4.1, 0.4.2, 0.4.3, 0.4.4,
      0.4.5.'']}'
    name: reproduce test outputs with ilastik 1.4.0b26 using tensorflow_saved_model_bundle
      weights
    reason: error
    status: failed
    traceback: ["  File \"/usr/share/miniconda3/envs/ilastik-env/lib/python3.7/site-packages/bioimageio/core/resource_tests.py\",
        line 39, in test_model\n    model_rdf, weights_priority_order=None if weight_format
        is None else [weight_format]\n", "  File \"/usr/share/miniconda3/envs/ilastik-env/lib/python3.7/site-packages/bioimageio/core/resource_io/io_.py\",
        line 41, in load_resource_description\n    raw_rd = load_raw_resource_description(source,
        update_to_format=\"latest\")\n", "  File \"/usr/share/miniconda3/envs/ilastik-env/lib/python3.7/site-packages/bioimageio/spec/io_.py\",
        line 191, in load_raw_resource_description\n    raw_rd = schema.load(data)\n",
      "  File \"/usr/share/miniconda3/envs/ilastik-env/lib/python3.7/site-packages/marshmallow/schema.py\",
        line 718, in load\n    data, many=many, partial=partial, unknown=unknown,
        postprocess=True\n", "  File \"/usr/share/miniconda3/envs/ilastik-env/lib/python3.7/site-packages/marshmallow/schema.py\",
        line 900, in _do_load\n    raise exc\n"]
  - bioimageio_core_version: 0.5.3post2
    bioimageio_spec_version: 0.4.5post6
    error: '{''format_version'': [''Must be one of: 0.4.0, 0.4.1, 0.4.2, 0.4.3, 0.4.4,
      0.4.5.'']}'
    name: reproduce test outputs with ilastik 1.4.0b27 using keras_hdf5 weights
    reason: error
    status: failed
    traceback: ["  File \"/usr/share/miniconda3/envs/ilastik-env/lib/python3.7/site-packages/bioimageio/core/resource_tests.py\",
        line 39, in test_model\n    model_rdf, weights_priority_order=None if weight_format
        is None else [weight_format]\n", "  File \"/usr/share/miniconda3/envs/ilastik-env/lib/python3.7/site-packages/bioimageio/core/resource_io/io_.py\",
        line 47, in load_resource_description\n    raw_rd = load_raw_resource_description(source,
        update_to_format=\"latest\")\n", "  File \"/usr/share/miniconda3/envs/ilastik-env/lib/python3.7/site-packages/bioimageio/spec/io_.py\",
        line 197, in load_raw_resource_description\n    raw_rd = schema.load(data)\n",
      "  File \"/usr/share/miniconda3/envs/ilastik-env/lib/python3.7/site-packages/marshmallow/schema.py\",
        line 718, in load\n    data, many=many, partial=partial, unknown=unknown,
        postprocess=True\n", "  File \"/usr/share/miniconda3/envs/ilastik-env/lib/python3.7/site-packages/marshmallow/schema.py\",
        line 900, in _do_load\n    raise exc\n"]
  - bioimageio_core_version: 0.5.3post2
    bioimageio_spec_version: 0.4.5post6
    error: '{''format_version'': [''Must be one of: 0.4.0, 0.4.1, 0.4.2, 0.4.3, 0.4.4,
      0.4.5.'']}'
    name: reproduce test outputs with ilastik 1.4.0b27 using tensorflow_saved_model_bundle
      weights
    reason: error
    status: failed
    traceback: ["  File \"/usr/share/miniconda3/envs/ilastik-env/lib/python3.7/site-packages/bioimageio/core/resource_tests.py\",
        line 39, in test_model\n    model_rdf, weights_priority_order=None if weight_format
        is None else [weight_format]\n", "  File \"/usr/share/miniconda3/envs/ilastik-env/lib/python3.7/site-packages/bioimageio/core/resource_io/io_.py\",
        line 47, in load_resource_description\n    raw_rd = load_raw_resource_description(source,
        update_to_format=\"latest\")\n", "  File \"/usr/share/miniconda3/envs/ilastik-env/lib/python3.7/site-packages/bioimageio/spec/io_.py\",
        line 197, in load_raw_resource_description\n    raw_rd = schema.load(data)\n",
      "  File \"/usr/share/miniconda3/envs/ilastik-env/lib/python3.7/site-packages/marshmallow/schema.py\",
        line 718, in load\n    data, many=many, partial=partial, unknown=unknown,
        postprocess=True\n", "  File \"/usr/share/miniconda3/envs/ilastik-env/lib/python3.7/site-packages/marshmallow/schema.py\",
        line 900, in _do_load\n    raise exc\n"]
  - {error: Missing/invalid weight formats for 10.5281/zenodo.5749843/5888237, name: reproduce
      test outputs with ilastik 1.4.0b27, reason: error, status: failed}
  - bioimageio_core_version: 0.5.1
    bioimageio_spec_version: 0.4.5post3
    error: '{''format_version'': [''Must be one of: 0.4.0, 0.4.1, 0.4.2, 0.4.3, 0.4.4,
      0.4.5.'']}'
    name: reproduce test outputs with ilastik 1.4.0b26 using keras_hdf5 weights
    reason: error
    status: failed
    traceback: ["  File \"/usr/share/miniconda3/envs/ilastik-env/lib/python3.7/site-packages/bioimageio/core/resource_tests.py\",
        line 39, in test_model\n    model_rdf, weights_priority_order=None if weight_format
        is None else [weight_format]\n", "  File \"/usr/share/miniconda3/envs/ilastik-env/lib/python3.7/site-packages/bioimageio/core/resource_io/io_.py\",
        line 41, in load_resource_description\n    raw_rd = load_raw_resource_description(source,
        update_to_format=\"latest\")\n", "  File \"/usr/share/miniconda3/envs/ilastik-env/lib/python3.7/site-packages/bioimageio/spec/io_.py\",
        line 191, in load_raw_resource_description\n    raw_rd = schema.load(data)\n",
      "  File \"/usr/share/miniconda3/envs/ilastik-env/lib/python3.7/site-packages/marshmallow/schema.py\",
        line 718, in load\n    data, many=many, partial=partial, unknown=unknown,
        postprocess=True\n", "  File \"/usr/share/miniconda3/envs/ilastik-env/lib/python3.7/site-packages/marshmallow/schema.py\",
        line 900, in _do_load\n    raise exc\n"]
  - {error: Missing/invalid weight formats for 10.5281/zenodo.5749843/5888237, name: reproduce
      test outputs with ilastik 1.4.0b26, reason: error, status: failed}
