bioimageio_core_version: 0.5.3.post2
bioimageio_spec_version: 0.4.8.post1
rdf_sha256: da56c59e7066452cc940a33b2ec6f3adbacea1032cfc6ff8c2f4ac8268405693
status: failed
tests:
  bioimageio:
  - bioimageio_spec_version: 0.4.8post1
    error: null
    name: bioimageio.spec static validation of model RDF 0.4.8 with update to latest
      format version
    nested_errors: {}
    status: passed
    traceback: null
    warnings: {license: BSD-2-Clause (BSD 2-Clause "Simplified" License) is not FSF
        Free/libre., tags: 'Missing tags for categories: [{''modality'': [''electron-microscopy'',
        ''cryo-electron-microscopy'', ''fluorescence-light-microscopy'', ''transmission-light-microscopy'',
        ''super-resolution-microscopy'', ''x-ray-microscopy'', ''force-microscopy'',
        ''high-content-imaging'', ''whole-slide-imaging'', ''other'']}, {''content'':
        [''cells'', ''nuclei'', ''extracellular-vesicles'', ''tissue'', ''plant'',
        ''mitochondria'', ''vasculature'', ''cell-membrane'', ''brain'', ''whole-organism'']},
        {''task'': [''semantic-segmentation'', ''instance-segmentation'', ''object-detection'',
        ''image-classification'', ''denoising'', ''image-restoration'', ''image-reconstruction'',
        ''in-silico-labeling'']}]'}
  - bioimageio_spec_version: 0.4.8post1
    error: null
    name: bioimageio.spec static validation of model RDF 0.4.8
    nested_errors: {}
    status: passed
    traceback: null
    warnings: {license: BSD-2-Clause (BSD 2-Clause "Simplified" License) is not FSF
        Free/libre., tags: 'Missing tags for categories: [{''modality'': [''electron-microscopy'',
        ''cryo-electron-microscopy'', ''fluorescence-light-microscopy'', ''transmission-light-microscopy'',
        ''super-resolution-microscopy'', ''x-ray-microscopy'', ''force-microscopy'',
        ''high-content-imaging'', ''whole-slide-imaging'', ''other'']}, {''content'':
        [''cells'', ''nuclei'', ''extracellular-vesicles'', ''tissue'', ''plant'',
        ''mitochondria'', ''vasculature'', ''cell-membrane'', ''brain'', ''whole-organism'']},
        {''task'': [''semantic-segmentation'', ''instance-segmentation'', ''object-detection'',
        ''image-classification'', ''denoising'', ''image-restoration'', ''image-reconstruction'',
        ''in-silico-labeling'']}]'}
  - error: No module named 'tqdm'
    name: import test_resource from test environment
    status: failed
    traceback: ["  File \"scripts/dynamic_validation.py\", line 41, in main\n    from
        bioimageio.core.resource_tests import test_resource\n", "  File \"/home/runner/micromamba-root/envs/5914249/lib/python3.7/site-packages/bioimageio/core/__init__.py\",
        line 13, in <module>\n    from .prediction_pipeline import create_prediction_pipeline\n",
      "  File \"/home/runner/micromamba-root/envs/5914249/lib/python3.7/site-packages/bioimageio/core/prediction_pipeline/__init__.py\",
        line 2, in <module>\n    from ._prediction_pipeline import PredictionPipeline,
        create_prediction_pipeline\n", "  File \"/home/runner/micromamba-root/envs/5914249/lib/python3.7/site-packages/bioimageio/core/prediction_pipeline/_prediction_pipeline.py\",
        line 12, in <module>\n    from ._stat_state import StatsState\n", "  File
        \"/home/runner/micromamba-root/envs/5914249/lib/python3.7/site-packages/bioimageio/core/prediction_pipeline/_stat_state.py\",
        line 3, in <module>\n    from tqdm import tqdm\n"]
  deepimagej:
  - {bioimageio_spec_version: 0.4.8post1, name: Reproduce test outputs with DeepImageJ
      headless, status: passed}
  ilastik:
  - {bioimageio_core_version: 0.5.1, bioimageio_spec_version: 0.4.5post3, error: null,
    name: reproduce test outputs with ilastik 1.4.0b26 using tensorflow_saved_model_bundle
      weights, reason: null, status: passed, traceback: null}
  - bioimageio_core_version: 0.5.3post2
    bioimageio_spec_version: 0.4.5post6
    error: '''str'' object has no attribute ''decode'''
    name: reproduce test outputs with ilastik 1.4.0b27 using keras_hdf5 weights
    reason: error
    status: failed
    traceback: ["  File \"/usr/share/miniconda3/envs/ilastik-env/lib/python3.7/site-packages/bioimageio/core/resource_tests.py\",
        line 148, in test_resource\n    bioimageio_model=model, devices=devices, weight_format=weight_format\n",
      "  File \"/usr/share/miniconda3/envs/ilastik-env/lib/python3.7/site-packages/bioimageio/core/prediction_pipeline/_prediction_pipeline.py\",
        line 114, in __enter__\n    self.load()\n", "  File \"/usr/share/miniconda3/envs/ilastik-env/lib/python3.7/site-packages/bioimageio/core/prediction_pipeline/_prediction_pipeline.py\",
        line 172, in load\n    self._model.load()\n", "  File \"/usr/share/miniconda3/envs/ilastik-env/lib/python3.7/site-packages/bioimageio/core/prediction_pipeline/_model_adapters/_model_adapter.py\",
        line 41, in load\n    self._load(devices=devices or self.default_devices)\n",
      "  File \"/usr/share/miniconda3/envs/ilastik-env/lib/python3.7/site-packages/bioimageio/core/prediction_pipeline/_model_adapters/_keras_model_adapter.py\",
        line 41, in _load\n    self._model = keras.models.load_model(weight_file)\n",
      "  File \"/usr/share/miniconda3/envs/ilastik-env/lib/python3.7/site-packages/tensorflow/python/keras/saving/save.py\",
        line 146, in load_model\n    return hdf5_format.load_model_from_hdf5(filepath,
        custom_objects, compile)\n", "  File \"/usr/share/miniconda3/envs/ilastik-env/lib/python3.7/site-packages/tensorflow/python/keras/saving/hdf5_format.py\",
        line 210, in load_model_from_hdf5\n    model_config = json.loads(model_config.decode('utf-8'))\n"]
  - bioimageio_core_version: 0.5.7
    bioimageio_spec_version: 0.4.8
    error: null
    name: load resource description
    status: passed
    traceback: null
    warnings: {}
  - {error: null, name: has expected resource type, status: passed, traceback: null}
  - bioimageio_core_version: 0.5.7
    bioimageio_spec_version: 0.4.8
    error: null
    name: All URLs and paths available
    nested_errors: null
    status: passed
    traceback: null
    warnings: {}
  - bioimageio_core_version: 0.5.7
    bioimageio_spec_version: 0.4.8
    error: null
    name: Test documentation completeness.
    status: passed
    traceback: null
    warnings: {documentation: No '# Validation' (sub)section found.}
  - bioimageio_core_version: 0.5.7
    bioimageio_spec_version: 0.4.8
    error: null
    name: reproduce test outputs from test inputs
    status: passed
    traceback: null
    warnings:
      non-validation-warnings: ['Device management is not implemented for keras yet,
          cannot unload model', Computed dataset percentiles naively by averaging
          percentiles of samples., 'Model tensorflow version (1, 15) does not match
          1.14.0.The prediction results may be wrong']
  - bioimageio_core_version: 0.5.8
    bioimageio_spec_version: 0.4.9
    error: null
    name: load resource description
    nested_errors: null
    status: passed
    traceback: null
    warnings: {}
  - {error: null, name: has expected resource type, status: passed, traceback: null}
  - bioimageio_core_version: 0.5.8
    bioimageio_spec_version: 0.4.9
    error: null
    name: All URLs and paths available
    nested_errors: null
    status: passed
    traceback: null
    warnings: {}
  - bioimageio_core_version: 0.5.8
    bioimageio_spec_version: 0.4.9
    error: null
    name: Test documentation completeness.
    status: passed
    traceback: null
    warnings: {documentation: No '# Validation' (sub)section found.}
  - bioimageio_core_version: 0.5.8
    bioimageio_spec_version: 0.4.9
    error: '''str'' object has no attribute ''decode'''
    name: reproduce test outputs from test inputs
    status: failed
    traceback: ["  File \"/usr/share/miniconda3/envs/ilastik-env/lib/python3.7/site-packages/bioimageio/core/resource_tests.py\",
        line 157, in _test_model_inference\n    bioimageio_model=model, devices=devices,
        weight_format=weight_format\n", "  File \"/usr/share/miniconda3/envs/ilastik-env/lib/python3.7/site-packages/bioimageio/core/prediction_pipeline/_prediction_pipeline.py\",
        line 122, in __enter__\n    self.load()\n", "  File \"/usr/share/miniconda3/envs/ilastik-env/lib/python3.7/site-packages/bioimageio/core/prediction_pipeline/_prediction_pipeline.py\",
        line 180, in load\n    self._model.load()\n", "  File \"/usr/share/miniconda3/envs/ilastik-env/lib/python3.7/site-packages/bioimageio/core/prediction_pipeline/_model_adapters/_model_adapter.py\",
        line 57, in load\n    self._load(devices=devices or self.default_devices)\n",
      "  File \"/usr/share/miniconda3/envs/ilastik-env/lib/python3.7/site-packages/bioimageio/core/prediction_pipeline/_model_adapters/_keras_model_adapter.py\",
        line 41, in _load\n    self._model = keras.models.load_model(weight_file)\n",
      "  File \"/usr/share/miniconda3/envs/ilastik-env/lib/python3.7/site-packages/tensorflow/python/keras/saving/save.py\",
        line 146, in load_model\n    return hdf5_format.load_model_from_hdf5(filepath,
        custom_objects, compile)\n", "  File \"/usr/share/miniconda3/envs/ilastik-env/lib/python3.7/site-packages/tensorflow/python/keras/saving/hdf5_format.py\",
        line 210, in load_model_from_hdf5\n    model_config = json.loads(model_config.decode('utf-8'))\n"]
    warnings:
      non-validation-warnings: ['Model tensorflow version (1, 15) does not match 1.14.0.The
          prediction results may be wrong']
  - {bioimageio_core_version: 0.5.3post2, bioimageio_spec_version: 0.4.5post6, error: null,
    name: reproduce test outputs with ilastik 1.4.0b27 using tensorflow_saved_model_bundle
      weights, reason: null, status: passed, traceback: null}
  - bioimageio_core_version: 0.5.8
    bioimageio_spec_version: 0.4.9
    error: null
    name: load resource description
    nested_errors: null
    status: passed
    traceback: null
    warnings: {}
  - {error: null, name: has expected resource type, status: passed, traceback: null}
  - bioimageio_core_version: 0.5.8
    bioimageio_spec_version: 0.4.9
    error: null
    name: All URLs and paths available
    nested_errors: null
    status: passed
    traceback: null
    warnings: {}
  - bioimageio_core_version: 0.5.8
    bioimageio_spec_version: 0.4.9
    error: null
    name: Test documentation completeness.
    status: passed
    traceback: null
    warnings: {documentation: No '# Validation' (sub)section found.}
  - bioimageio_core_version: 0.5.8
    bioimageio_spec_version: 0.4.9
    error: null
    name: reproduce test outputs from test inputs
    status: passed
    traceback: null
    warnings:
      non-validation-warnings: ['Device management is not implemented for keras yet,
          cannot unload model', 'Model tensorflow version (1, 15) does not match 1.14.0.The
          prediction results may be wrong', Computed dataset percentiles naively by
          averaging percentiles of samples.]
  - {error: Missing/invalid weight formats for 10.5281/zenodo.5914248/5914249, name: reproduce
      test outputs with ilastik 1.4.0b27, reason: error, status: failed}
  - bioimageio_core_version: 0.5.1
    bioimageio_spec_version: 0.4.5post3
    error: '''str'' object has no attribute ''decode'''
    name: reproduce test outputs with ilastik 1.4.0b26 using keras_hdf5 weights
    reason: error
    status: failed
    traceback: ["  File \"/usr/share/miniconda3/envs/ilastik-env/lib/python3.7/site-packages/bioimageio/core/resource_tests.py\",
        line 148, in test_resource\n    bioimageio_model=model, devices=devices, weight_format=weight_format\n",
      "  File \"/usr/share/miniconda3/envs/ilastik-env/lib/python3.7/site-packages/bioimageio/core/prediction_pipeline/_prediction_pipeline.py\",
        line 103, in __enter__\n    self.load()\n", "  File \"/usr/share/miniconda3/envs/ilastik-env/lib/python3.7/site-packages/bioimageio/core/prediction_pipeline/_prediction_pipeline.py\",
        line 143, in load\n    self._model.load()\n", "  File \"/usr/share/miniconda3/envs/ilastik-env/lib/python3.7/site-packages/bioimageio/core/prediction_pipeline/_model_adapters/_model_adapter.py\",
        line 41, in load\n    self._load(devices=devices or self.default_devices)\n",
      "  File \"/usr/share/miniconda3/envs/ilastik-env/lib/python3.7/site-packages/bioimageio/core/prediction_pipeline/_model_adapters/_keras_model_adapter.py\",
        line 39, in _load\n    self._model = keras.models.load_model(weight_file)\n",
      "  File \"/usr/share/miniconda3/envs/ilastik-env/lib/python3.7/site-packages/tensorflow/python/keras/saving/save.py\",
        line 146, in load_model\n    return hdf5_format.load_model_from_hdf5(filepath,
        custom_objects, compile)\n", "  File \"/usr/share/miniconda3/envs/ilastik-env/lib/python3.7/site-packages/tensorflow/python/keras/saving/hdf5_format.py\",
        line 210, in load_model_from_hdf5\n    model_config = json.loads(model_config.decode('utf-8'))\n"]
  - bioimageio_core_version: 0.5.7
    bioimageio_spec_version: 0.4.8
    error: null
    name: load resource description
    status: passed
    traceback: null
    warnings: {}
  - {error: null, name: has expected resource type, status: passed, traceback: null}
  - bioimageio_core_version: 0.5.7
    bioimageio_spec_version: 0.4.8
    error: null
    name: All URLs and paths available
    nested_errors: null
    status: passed
    traceback: null
    warnings: {}
  - bioimageio_core_version: 0.5.7
    bioimageio_spec_version: 0.4.8
    error: null
    name: Test documentation completeness.
    status: passed
    traceback: null
    warnings: {documentation: No '# Validation' (sub)section found.}
  - bioimageio_core_version: 0.5.7
    bioimageio_spec_version: 0.4.8
    error: '''str'' object has no attribute ''decode'''
    name: reproduce test outputs from test inputs
    status: failed
    traceback: ["  File \"/usr/share/miniconda3/envs/ilastik-env/lib/python3.7/site-packages/bioimageio/core/resource_tests.py\",
        line 157, in _test_model_inference\n    bioimageio_model=model, devices=devices,
        weight_format=weight_format\n", "  File \"/usr/share/miniconda3/envs/ilastik-env/lib/python3.7/site-packages/bioimageio/core/prediction_pipeline/_prediction_pipeline.py\",
        line 122, in __enter__\n    self.load()\n", "  File \"/usr/share/miniconda3/envs/ilastik-env/lib/python3.7/site-packages/bioimageio/core/prediction_pipeline/_prediction_pipeline.py\",
        line 180, in load\n    self._model.load()\n", "  File \"/usr/share/miniconda3/envs/ilastik-env/lib/python3.7/site-packages/bioimageio/core/prediction_pipeline/_model_adapters/_model_adapter.py\",
        line 57, in load\n    self._load(devices=devices or self.default_devices)\n",
      "  File \"/usr/share/miniconda3/envs/ilastik-env/lib/python3.7/site-packages/bioimageio/core/prediction_pipeline/_model_adapters/_keras_model_adapter.py\",
        line 41, in _load\n    self._model = keras.models.load_model(weight_file)\n",
      "  File \"/usr/share/miniconda3/envs/ilastik-env/lib/python3.7/site-packages/tensorflow/python/keras/saving/save.py\",
        line 146, in load_model\n    return hdf5_format.load_model_from_hdf5(filepath,
        custom_objects, compile)\n", "  File \"/usr/share/miniconda3/envs/ilastik-env/lib/python3.7/site-packages/tensorflow/python/keras/saving/hdf5_format.py\",
        line 210, in load_model_from_hdf5\n    model_config = json.loads(model_config.decode('utf-8'))\n"]
    warnings:
      non-validation-warnings: ['Model tensorflow version (1, 15) does not match 1.14.0.The
          prediction results may be wrong']
  - {error: Missing/invalid weight formats for 10.5281/zenodo.5914248/5914249, name: reproduce
      test outputs with ilastik 1.4.0b26, reason: error, status: failed}
