error: '[Errno 2] No such file or directory: ''dist/resources/zero/Notebook_U-Net_3D_ZeroCostDL4Mic/latest/rdf.yaml'''
name: bioimageio.spec static validation
nested_errors: {}
source_name: dist/resources/zero/Notebook_U-Net_3D_ZeroCostDL4Mic/latest/rdf.yaml
traceback: ["  File \"/home/runner/.local/lib/python3.8/site-packages/bioimageio/spec/commands.py\",
    line 55, in validate\n    rdf_source, source_name, root = resolve_rdf_source(rdf_source)\n",
  "  File \"/home/runner/.local/lib/python3.8/site-packages/bioimageio/spec/shared/utils/_resolve_source.py\",
    line 150, in resolve_rdf_source\n    source = yaml.load(source)\n", "  File \"/home/runner/.local/lib/python3.8/site-packages/ruamel/yaml/main.py\",
    line 430, in load\n    with stream.open('rb') as fp:\n", "  File \"/usr/lib/python3.8/pathlib.py\",
    line 1222, in open\n    return io.open(self, mode, buffering, encoding, errors,
    newline,\n", "  File \"/usr/lib/python3.8/pathlib.py\", line 1078, in _opener\n
    \   return self._accessor.open(self, flags, mode)\n"]
warnings: {}
