bioimageio_spec_version: 0.4.8.post1
rdf_sha256: 0170669407f703cb5db80459f84768a643d45c76651f2c6abcf6a36bbdbb2f5f
status: failed
tests:
  bioimageio:
  - bioimageio_spec_version: 0.4.8post1
    error: null
    name: bioimageio.spec static validation of model RDF 0.4.8 with update to latest
      format version
    nested_errors: {}
    status: passed
    traceback: null
    warnings: {tags: 'Missing tags for categories: [{''network'': [''unet'', ''densenet'',
        ''resnet'', ''inception'', ''shufflenet'']}]'}
  - bioimageio_spec_version: 0.4.8post1
    error: null
    name: bioimageio.spec static validation of model RDF 0.4.8
    nested_errors: {}
    status: passed
    traceback: null
    warnings: {tags: 'Missing tags for categories: [{''network'': [''unet'', ''densenet'',
        ''resnet'', ''inception'', ''shufflenet'']}]'}
  - error: No module named 'tqdm'
    name: import test_resource from test environment
    status: failed
    traceback: ["  File \"scripts/dynamic_validation.py\", line 41, in main\n    from
        bioimageio.core.resource_tests import test_resource\n", "  File \"/home/runner/micromamba-root/envs/6559475/lib/python3.7/site-packages/bioimageio/core/__init__.py\",
        line 13, in <module>\n    from .prediction_pipeline import create_prediction_pipeline\n",
      "  File \"/home/runner/micromamba-root/envs/6559475/lib/python3.7/site-packages/bioimageio/core/prediction_pipeline/__init__.py\",
        line 2, in <module>\n    from ._prediction_pipeline import PredictionPipeline,
        create_prediction_pipeline\n", "  File \"/home/runner/micromamba-root/envs/6559475/lib/python3.7/site-packages/bioimageio/core/prediction_pipeline/_prediction_pipeline.py\",
        line 12, in <module>\n    from ._stat_state import StatsState\n", "  File
        \"/home/runner/micromamba-root/envs/6559475/lib/python3.7/site-packages/bioimageio/core/prediction_pipeline/_stat_state.py\",
        line 3, in <module>\n    from tqdm import tqdm\n"]
  deepimagej:
  - {bioimageio_spec_version: 0.4.8post1, error: Error while running DeepImageJ headless
      (CI did not produce an output image), name: Reproduce test outputs with DeepImageJ
      headless, status: failed}
  ilastik:
  - bioimageio_core_version: 0.5.7
    bioimageio_spec_version: 0.4.8
    error: null
    name: load resource description
    status: passed
    traceback: null
    warnings: {}
  - {error: null, name: has expected resource type, status: passed, traceback: null}
  - bioimageio_core_version: 0.5.7
    bioimageio_spec_version: 0.4.8
    error: null
    name: All URLs and paths available
    nested_errors: null
    status: passed
    traceback: null
    warnings: {}
  - bioimageio_core_version: 0.5.7
    bioimageio_spec_version: 0.4.8
    error: null
    name: Test documentation completeness.
    status: passed
    traceback: null
    warnings: {documentation: No '# Validation' (sub)section found.}
  - bioimageio_core_version: 0.5.7
    bioimageio_spec_version: 0.4.8
    error: Weight format tensorflow_js is not in supported formats ['pytorch_state_dict',
      'tensorflow_saved_model_bundle', 'torchscript', 'onnx', 'keras_hdf5']
    name: reproduce test outputs from test inputs
    status: failed
    traceback: ["  File \"/usr/share/miniconda3/envs/ilastik-env/lib/python3.7/site-packages/bioimageio/core/resource_tests.py\",
        line 157, in _test_model_inference\n    bioimageio_model=model, devices=devices,
        weight_format=weight_format\n", "  File \"/usr/share/miniconda3/envs/ilastik-env/lib/python3.7/site-packages/bioimageio/core/prediction_pipeline/_prediction_pipeline.py\",
        line 205, in create_prediction_pipeline\n    bioimageio_model=bioimageio_model,
        devices=devices, weight_format=weight_format\n", "  File \"/usr/share/miniconda3/envs/ilastik-env/lib/python3.7/site-packages/bioimageio/core/prediction_pipeline/_model_adapters/_model_adapter.py\",
        line 127, in create_model_adapter\n    raise ValueError(f\"Weight format {weight_format}
        is not in supported formats {weight_formats}\")\n"]
    warnings: {}
  - bioimageio_core_version: 0.5.7
    bioimageio_spec_version: 0.4.8
    error: null
    name: load resource description
    status: passed
    traceback: null
    warnings: {}
  - {error: null, name: has expected resource type, status: passed, traceback: null}
  - bioimageio_core_version: 0.5.7
    bioimageio_spec_version: 0.4.8
    error: null
    name: All URLs and paths available
    nested_errors: null
    status: passed
    traceback: null
    warnings: {}
  - bioimageio_core_version: 0.5.7
    bioimageio_spec_version: 0.4.8
    error: null
    name: Test documentation completeness.
    status: passed
    traceback: null
    warnings: {documentation: No '# Validation' (sub)section found.}
  - bioimageio_core_version: 0.5.7
    bioimageio_spec_version: 0.4.8
    error: '''str'' object has no attribute ''decode'''
    name: reproduce test outputs from test inputs
    status: failed
    traceback: ["  File \"/usr/share/miniconda3/envs/ilastik-env/lib/python3.7/site-packages/bioimageio/core/resource_tests.py\",
        line 157, in _test_model_inference\n    bioimageio_model=model, devices=devices,
        weight_format=weight_format\n", "  File \"/usr/share/miniconda3/envs/ilastik-env/lib/python3.7/site-packages/bioimageio/core/prediction_pipeline/_prediction_pipeline.py\",
        line 122, in __enter__\n    self.load()\n", "  File \"/usr/share/miniconda3/envs/ilastik-env/lib/python3.7/site-packages/bioimageio/core/prediction_pipeline/_prediction_pipeline.py\",
        line 180, in load\n    self._model.load()\n", "  File \"/usr/share/miniconda3/envs/ilastik-env/lib/python3.7/site-packages/bioimageio/core/prediction_pipeline/_model_adapters/_model_adapter.py\",
        line 57, in load\n    self._load(devices=devices or self.default_devices)\n",
      "  File \"/usr/share/miniconda3/envs/ilastik-env/lib/python3.7/site-packages/bioimageio/core/prediction_pipeline/_model_adapters/_keras_model_adapter.py\",
        line 41, in _load\n    self._model = keras.models.load_model(weight_file)\n",
      "  File \"/usr/share/miniconda3/envs/ilastik-env/lib/python3.7/site-packages/tensorflow/python/keras/saving/save.py\",
        line 146, in load_model\n    return hdf5_format.load_model_from_hdf5(filepath,
        custom_objects, compile)\n", "  File \"/usr/share/miniconda3/envs/ilastik-env/lib/python3.7/site-packages/tensorflow/python/keras/saving/hdf5_format.py\",
        line 210, in load_model_from_hdf5\n    model_config = json.loads(model_config.decode('utf-8'))\n"]
    warnings:
      non-validation-warnings: ['Model tensorflow version (1, 12) does not match 1.14.0.The
          prediction results may be wrong']
  - bioimageio_core_version: 0.5.8
    bioimageio_spec_version: 0.4.9
    error: null
    name: load resource description
    nested_errors: null
    status: passed
    traceback: null
    warnings: {}
  - {error: null, name: has expected resource type, status: passed, traceback: null}
  - bioimageio_core_version: 0.5.8
    bioimageio_spec_version: 0.4.9
    error: null
    name: All URLs and paths available
    nested_errors: null
    status: passed
    traceback: null
    warnings: {}
  - bioimageio_core_version: 0.5.8
    bioimageio_spec_version: 0.4.9
    error: null
    name: Test documentation completeness.
    status: passed
    traceback: null
    warnings: {documentation: No '# Validation' (sub)section found.}
  - bioimageio_core_version: 0.5.8
    bioimageio_spec_version: 0.4.9
    error: '''str'' object has no attribute ''decode'''
    name: reproduce test outputs from test inputs
    status: failed
    traceback: ["  File \"/usr/share/miniconda3/envs/ilastik-env/lib/python3.7/site-packages/bioimageio/core/resource_tests.py\",
        line 157, in _test_model_inference\n    bioimageio_model=model, devices=devices,
        weight_format=weight_format\n", "  File \"/usr/share/miniconda3/envs/ilastik-env/lib/python3.7/site-packages/bioimageio/core/prediction_pipeline/_prediction_pipeline.py\",
        line 122, in __enter__\n    self.load()\n", "  File \"/usr/share/miniconda3/envs/ilastik-env/lib/python3.7/site-packages/bioimageio/core/prediction_pipeline/_prediction_pipeline.py\",
        line 180, in load\n    self._model.load()\n", "  File \"/usr/share/miniconda3/envs/ilastik-env/lib/python3.7/site-packages/bioimageio/core/prediction_pipeline/_model_adapters/_model_adapter.py\",
        line 57, in load\n    self._load(devices=devices or self.default_devices)\n",
      "  File \"/usr/share/miniconda3/envs/ilastik-env/lib/python3.7/site-packages/bioimageio/core/prediction_pipeline/_model_adapters/_keras_model_adapter.py\",
        line 41, in _load\n    self._model = keras.models.load_model(weight_file)\n",
      "  File \"/usr/share/miniconda3/envs/ilastik-env/lib/python3.7/site-packages/tensorflow/python/keras/saving/save.py\",
        line 146, in load_model\n    return hdf5_format.load_model_from_hdf5(filepath,
        custom_objects, compile)\n", "  File \"/usr/share/miniconda3/envs/ilastik-env/lib/python3.7/site-packages/tensorflow/python/keras/saving/hdf5_format.py\",
        line 210, in load_model_from_hdf5\n    model_config = json.loads(model_config.decode('utf-8'))\n"]
    warnings:
      non-validation-warnings: ['Model tensorflow version (1, 12) does not match 1.14.0.The
          prediction results may be wrong']
  - bioimageio_core_version: 0.5.8
    bioimageio_spec_version: 0.4.9
    error: null
    name: load resource description
    nested_errors: null
    status: passed
    traceback: null
    warnings: {}
  - {error: null, name: has expected resource type, status: passed, traceback: null}
  - bioimageio_core_version: 0.5.8
    bioimageio_spec_version: 0.4.9
    error: null
    name: All URLs and paths available
    nested_errors: null
    status: passed
    traceback: null
    warnings: {}
  - bioimageio_core_version: 0.5.8
    bioimageio_spec_version: 0.4.9
    error: null
    name: Test documentation completeness.
    status: passed
    traceback: null
    warnings: {documentation: No '# Validation' (sub)section found.}
  - bioimageio_core_version: 0.5.8
    bioimageio_spec_version: 0.4.9
    error: null
    name: reproduce test outputs from test inputs
    status: passed
    traceback: null
    warnings:
      non-validation-warnings: ['Device management is not implemented for keras yet,
          cannot unload model', 'Model tensorflow version (1, 12) does not match 1.14.0.The
          prediction results may be wrong', Computed dataset percentiles naively by
          averaging percentiles of samples.]
  - bioimageio_core_version: 0.5.7
    bioimageio_spec_version: 0.4.8
    error: null
    name: load resource description
    status: passed
    traceback: null
    warnings: {}
  - {error: null, name: has expected resource type, status: passed, traceback: null}
  - bioimageio_core_version: 0.5.7
    bioimageio_spec_version: 0.4.8
    error: null
    name: All URLs and paths available
    nested_errors: null
    status: passed
    traceback: null
    warnings: {}
  - bioimageio_core_version: 0.5.7
    bioimageio_spec_version: 0.4.8
    error: null
    name: Test documentation completeness.
    status: passed
    traceback: null
    warnings: {documentation: No '# Validation' (sub)section found.}
  - bioimageio_core_version: 0.5.7
    bioimageio_spec_version: 0.4.8
    error: null
    name: reproduce test outputs from test inputs
    status: passed
    traceback: null
    warnings:
      non-validation-warnings: [Computed dataset percentiles naively by averaging
          percentiles of samples., 'Device management is not implemented for keras
          yet, cannot unload model', 'Model tensorflow version (1, 12) does not match
          1.14.0.The prediction results may be wrong']
  - bioimageio_core_version: 0.5.8
    bioimageio_spec_version: 0.4.9
    error: null
    name: load resource description
    nested_errors: null
    status: passed
    traceback: null
    warnings: {}
  - {error: null, name: has expected resource type, status: passed, traceback: null}
  - bioimageio_core_version: 0.5.8
    bioimageio_spec_version: 0.4.9
    error: null
    name: All URLs and paths available
    nested_errors: null
    status: passed
    traceback: null
    warnings: {}
  - bioimageio_core_version: 0.5.8
    bioimageio_spec_version: 0.4.9
    error: null
    name: Test documentation completeness.
    status: passed
    traceback: null
    warnings: {documentation: No '# Validation' (sub)section found.}
  - bioimageio_core_version: 0.5.8
    bioimageio_spec_version: 0.4.9
    error: Weight format tensorflow_js is not in supported formats ['pytorch_state_dict',
      'tensorflow_saved_model_bundle', 'torchscript', 'onnx', 'keras_hdf5']
    name: reproduce test outputs from test inputs
    status: failed
    traceback: ["  File \"/usr/share/miniconda3/envs/ilastik-env/lib/python3.7/site-packages/bioimageio/core/resource_tests.py\",
        line 157, in _test_model_inference\n    bioimageio_model=model, devices=devices,
        weight_format=weight_format\n", "  File \"/usr/share/miniconda3/envs/ilastik-env/lib/python3.7/site-packages/bioimageio/core/prediction_pipeline/_prediction_pipeline.py\",
        line 205, in create_prediction_pipeline\n    bioimageio_model=bioimageio_model,
        devices=devices, weight_format=weight_format\n", "  File \"/usr/share/miniconda3/envs/ilastik-env/lib/python3.7/site-packages/bioimageio/core/prediction_pipeline/_model_adapters/_model_adapter.py\",
        line 127, in create_model_adapter\n    raise ValueError(f\"Weight format {weight_format}
        is not in supported formats {weight_formats}\")\n"]
    warnings: {}
